[2025-03-04T20:19:42.869+0000] {local_task_job_runner.py:123} INFO - ::group::Pre task execution logs
[2025-03-04T20:19:42.937+0000] {taskinstance.py:2614} INFO - Dependencies all met for dep_context=non-requeueable deps ti=<TaskInstance: fraud_detection_training.execute_training manual__2025-03-04T20:19:36.656268+00:00 [queued]>
[2025-03-04T20:19:42.949+0000] {taskinstance.py:2614} INFO - Dependencies all met for dep_context=requeueable deps ti=<TaskInstance: fraud_detection_training.execute_training manual__2025-03-04T20:19:36.656268+00:00 [queued]>
[2025-03-04T20:19:42.949+0000] {taskinstance.py:2867} INFO - Starting attempt 1 of 1
[2025-03-04T20:19:42.972+0000] {taskinstance.py:2890} INFO - Executing <Task(PythonOperator): execute_training> on 2025-03-04 20:19:36.656268+00:00
[2025-03-04T20:19:42.978+0000] {warnings.py:112} WARNING - /home/***/.local/lib/python3.12/site-packages/***/task/task_runner/standard_task_runner.py:70: DeprecationWarning: This process (pid=9348) is multi-threaded, use of fork() may lead to deadlocks in the child.
  pid = os.fork()

[2025-03-04T20:19:42.978+0000] {standard_task_runner.py:104} INFO - Running: ['***', 'tasks', 'run', 'fraud_detection_training', 'execute_training', 'manual__2025-03-04T20:19:36.656268+00:00', '--job-id', '28', '--raw', '--subdir', 'DAGS_FOLDER/fraud_detection_training_dag.py', '--cfg-path', '/tmp/tmpwx7pdhp6']
[2025-03-04T20:19:42.980+0000] {standard_task_runner.py:105} INFO - Job 28: Subtask execute_training
[2025-03-04T20:19:42.980+0000] {standard_task_runner.py:72} INFO - Started process 9349 to run task
[2025-03-04T20:19:43.151+0000] {task_command.py:467} INFO - Running <TaskInstance: fraud_detection_training.execute_training manual__2025-03-04T20:19:36.656268+00:00 [running]> on host b7f28f610775
[2025-03-04T20:19:43.460+0000] {taskinstance.py:3134} INFO - Exporting env vars: AIRFLOW_CTX_DAG_OWNER='datamasterylab.com' AIRFLOW_CTX_DAG_ID='fraud_detection_training' AIRFLOW_CTX_TASK_ID='execute_training' AIRFLOW_CTX_EXECUTION_DATE='2025-03-04T20:19:36.656268+00:00' AIRFLOW_CTX_TRY_NUMBER='1' AIRFLOW_CTX_DAG_RUN_ID='manual__2025-03-04T20:19:36.656268+00:00'
[2025-03-04T20:19:43.463+0000] {taskinstance.py:732} INFO - ::endgroup::
[2025-03-04T20:19:47.806+0000] {warnings.py:112} WARNING - /opt/***/dags/fraud_detection_training.py:15: UserWarning: The numpy.array_api submodule is still experimental. See NEP 47.
  from numpy.array_api import astype

[2025-03-04T20:19:47.952+0000] {fraud_detection_training_dag.py:23} INFO - Initializing fraud detection training
[2025-03-04T20:19:47.957+0000] {fraud_detection_training.py:58} INFO - Configuration loaded successfully
[2025-03-04T20:19:48.096+0000] {fraud_detection_training.py:83} INFO - Minio connection verified. Buckets: ['mlflow']
[2025-03-04T20:19:48.177+0000] {fraud_detection_training.py:170} INFO - Starting model training process
[2025-03-04T20:19:48.178+0000] {fraud_detection_training.py:96} INFO - Connecting to kafka topic transactions
[2025-03-04T20:19:48.302+0000] {conn.py:384} INFO - <BrokerConnection client_id=kafka-python-2.0.5, node_id=bootstrap-0 host=pkc-41wq6.eu-west-2.aws.confluent.cloud:9092 <connecting> [IPv4 ('18.134.120.81', 9092)]>: connecting to pkc-41wq6.eu-west-2.aws.confluent.cloud:9092 [('18.134.120.81', 9092) IPv4]
[2025-03-04T20:19:48.303+0000] {conn.py:1219} INFO - Probing node bootstrap-0 broker version
[2025-03-04T20:19:48.334+0000] {conn.py:480} INFO - <BrokerConnection client_id=kafka-python-2.0.5, node_id=bootstrap-0 host=pkc-41wq6.eu-west-2.aws.confluent.cloud:9092 <handshake> [IPv4 ('18.134.120.81', 9092)]>: Loading system default SSL CAs from ('/usr/lib/ssl/cert.pem', '/usr/lib/ssl/certs', 'SSL_CERT_FILE', '/usr/lib/ssl/cert.pem', 'SSL_CERT_DIR', '/usr/lib/ssl/certs')
[2025-03-04T20:19:48.799+0000] {conn.py:665} INFO - <BrokerConnection client_id=kafka-python-2.0.5, node_id=bootstrap-0 host=pkc-41wq6.eu-west-2.aws.confluent.cloud:9092 <authenticating> [IPv4 ('18.134.120.81', 9092)]>: Authenticated as XGISOSVJLGK43N6I via PLAIN
[2025-03-04T20:19:48.799+0000] {conn.py:449} INFO - <BrokerConnection client_id=kafka-python-2.0.5, node_id=bootstrap-0 host=pkc-41wq6.eu-west-2.aws.confluent.cloud:9092 <authenticating> [IPv4 ('18.134.120.81', 9092)]>: Connection complete.
[2025-03-04T20:19:49.002+0000] {conn.py:1282} INFO - Broker version identified as 2.6.0
[2025-03-04T20:19:49.003+0000] {conn.py:1283} INFO - Set configuration api_version=(2, 6, 0) to skip auto check_version requests on startup
[2025-03-04T20:19:49.009+0000] {consumer.py:118} WARNING - group_id is None: disabling auto-commit.
[2025-03-04T20:19:49.011+0000] {subscription_state.py:171} INFO - Updating subscribed topics to: ('transactions',)
[2025-03-04T20:19:49.101+0000] {subscription_state.py:257} INFO - Updated partition assignment: [('transactions', 0), ('transactions', 1), ('transactions', 2), ('transactions', 3), ('transactions', 4), ('transactions', 5)]
[2025-03-04T20:19:49.178+0000] {conn.py:384} INFO - <BrokerConnection client_id=kafka-python-2.0.5, node_id=4 host=b4-pkc-41wq6.eu-west-2.aws.confluent.cloud:9092 <connecting> [IPv4 ('52.56.207.193', 9092)]>: connecting to b4-pkc-41wq6.eu-west-2.aws.confluent.cloud:9092 [('52.56.207.193', 9092) IPv4]
[2025-03-04T20:19:49.284+0000] {conn.py:480} INFO - <BrokerConnection client_id=kafka-python-2.0.5, node_id=4 host=b4-pkc-41wq6.eu-west-2.aws.confluent.cloud:9092 <handshake> [IPv4 ('52.56.207.193', 9092)]>: Loading system default SSL CAs from ('/usr/lib/ssl/cert.pem', '/usr/lib/ssl/certs', 'SSL_CERT_FILE', '/usr/lib/ssl/cert.pem', 'SSL_CERT_DIR', '/usr/lib/ssl/certs')
[2025-03-04T20:19:49.738+0000] {conn.py:665} INFO - <BrokerConnection client_id=kafka-python-2.0.5, node_id=4 host=b4-pkc-41wq6.eu-west-2.aws.confluent.cloud:9092 <authenticating> [IPv4 ('52.56.207.193', 9092)]>: Authenticated as XGISOSVJLGK43N6I via PLAIN
[2025-03-04T20:19:49.739+0000] {conn.py:449} INFO - <BrokerConnection client_id=kafka-python-2.0.5, node_id=4 host=b4-pkc-41wq6.eu-west-2.aws.confluent.cloud:9092 <authenticating> [IPv4 ('52.56.207.193', 9092)]>: Connection complete.
[2025-03-04T20:19:49.741+0000] {conn.py:928} INFO - <BrokerConnection client_id=kafka-python-2.0.5, node_id=bootstrap-0 host=pkc-41wq6.eu-west-2.aws.confluent.cloud:9092 <connected> [IPv4 ('18.134.120.81', 9092)]>: Closing connection. 
[2025-03-04T20:19:49.894+0000] {conn.py:384} INFO - <BrokerConnection client_id=kafka-python-2.0.5, node_id=1 host=b1-pkc-41wq6.eu-west-2.aws.confluent.cloud:9092 <connecting> [IPv4 ('18.169.23.80', 9092)]>: connecting to b1-pkc-41wq6.eu-west-2.aws.confluent.cloud:9092 [('18.169.23.80', 9092) IPv4]
[2025-03-04T20:19:50.000+0000] {conn.py:480} INFO - <BrokerConnection client_id=kafka-python-2.0.5, node_id=1 host=b1-pkc-41wq6.eu-west-2.aws.confluent.cloud:9092 <handshake> [IPv4 ('18.169.23.80', 9092)]>: Loading system default SSL CAs from ('/usr/lib/ssl/cert.pem', '/usr/lib/ssl/certs', 'SSL_CERT_FILE', '/usr/lib/ssl/cert.pem', 'SSL_CERT_DIR', '/usr/lib/ssl/certs')
[2025-03-04T20:19:50.474+0000] {conn.py:665} INFO - <BrokerConnection client_id=kafka-python-2.0.5, node_id=1 host=b1-pkc-41wq6.eu-west-2.aws.confluent.cloud:9092 <authenticating> [IPv4 ('18.169.23.80', 9092)]>: Authenticated as XGISOSVJLGK43N6I via PLAIN
[2025-03-04T20:19:50.475+0000] {conn.py:449} INFO - <BrokerConnection client_id=kafka-python-2.0.5, node_id=1 host=b1-pkc-41wq6.eu-west-2.aws.confluent.cloud:9092 <authenticating> [IPv4 ('18.169.23.80', 9092)]>: Connection complete.
[2025-03-04T20:19:51.727+0000] {conn.py:384} INFO - <BrokerConnection client_id=kafka-python-2.0.5, node_id=2 host=b2-pkc-41wq6.eu-west-2.aws.confluent.cloud:9092 <connecting> [IPv4 ('13.43.33.231', 9092)]>: connecting to b2-pkc-41wq6.eu-west-2.aws.confluent.cloud:9092 [('13.43.33.231', 9092) IPv4]
[2025-03-04T20:19:51.838+0000] {conn.py:480} INFO - <BrokerConnection client_id=kafka-python-2.0.5, node_id=2 host=b2-pkc-41wq6.eu-west-2.aws.confluent.cloud:9092 <handshake> [IPv4 ('13.43.33.231', 9092)]>: Loading system default SSL CAs from ('/usr/lib/ssl/cert.pem', '/usr/lib/ssl/certs', 'SSL_CERT_FILE', '/usr/lib/ssl/cert.pem', 'SSL_CERT_DIR', '/usr/lib/ssl/certs')
[2025-03-04T20:19:52.338+0000] {conn.py:665} INFO - <BrokerConnection client_id=kafka-python-2.0.5, node_id=2 host=b2-pkc-41wq6.eu-west-2.aws.confluent.cloud:9092 <authenticating> [IPv4 ('13.43.33.231', 9092)]>: Authenticated as XGISOSVJLGK43N6I via PLAIN
[2025-03-04T20:19:52.340+0000] {conn.py:449} INFO - <BrokerConnection client_id=kafka-python-2.0.5, node_id=2 host=b2-pkc-41wq6.eu-west-2.aws.confluent.cloud:9092 <authenticating> [IPv4 ('13.43.33.231', 9092)]>: Connection complete.
[2025-03-04T20:19:52.485+0000] {conn.py:384} INFO - <BrokerConnection client_id=kafka-python-2.0.5, node_id=5 host=b5-pkc-41wq6.eu-west-2.aws.confluent.cloud:9092 <connecting> [IPv4 ('51.24.25.161', 9092)]>: connecting to b5-pkc-41wq6.eu-west-2.aws.confluent.cloud:9092 [('51.24.25.161', 9092) IPv4]
[2025-03-04T20:19:52.597+0000] {conn.py:480} INFO - <BrokerConnection client_id=kafka-python-2.0.5, node_id=5 host=b5-pkc-41wq6.eu-west-2.aws.confluent.cloud:9092 <handshake> [IPv4 ('51.24.25.161', 9092)]>: Loading system default SSL CAs from ('/usr/lib/ssl/cert.pem', '/usr/lib/ssl/certs', 'SSL_CERT_FILE', '/usr/lib/ssl/cert.pem', 'SSL_CERT_DIR', '/usr/lib/ssl/certs')
[2025-03-04T20:19:52.972+0000] {conn.py:665} INFO - <BrokerConnection client_id=kafka-python-2.0.5, node_id=5 host=b5-pkc-41wq6.eu-west-2.aws.confluent.cloud:9092 <authenticating> [IPv4 ('51.24.25.161', 9092)]>: Authenticated as XGISOSVJLGK43N6I via PLAIN
[2025-03-04T20:19:52.974+0000] {conn.py:449} INFO - <BrokerConnection client_id=kafka-python-2.0.5, node_id=5 host=b5-pkc-41wq6.eu-west-2.aws.confluent.cloud:9092 <authenticating> [IPv4 ('51.24.25.161', 9092)]>: Connection complete.
[2025-03-04T20:19:53.114+0000] {conn.py:384} INFO - <BrokerConnection client_id=kafka-python-2.0.5, node_id=3 host=b3-pkc-41wq6.eu-west-2.aws.confluent.cloud:9092 <connecting> [IPv4 ('13.43.118.221', 9092)]>: connecting to b3-pkc-41wq6.eu-west-2.aws.confluent.cloud:9092 [('13.43.118.221', 9092) IPv4]
[2025-03-04T20:19:53.225+0000] {conn.py:480} INFO - <BrokerConnection client_id=kafka-python-2.0.5, node_id=3 host=b3-pkc-41wq6.eu-west-2.aws.confluent.cloud:9092 <handshake> [IPv4 ('13.43.118.221', 9092)]>: Loading system default SSL CAs from ('/usr/lib/ssl/cert.pem', '/usr/lib/ssl/certs', 'SSL_CERT_FILE', '/usr/lib/ssl/cert.pem', 'SSL_CERT_DIR', '/usr/lib/ssl/certs')
[2025-03-04T20:19:53.675+0000] {conn.py:665} INFO - <BrokerConnection client_id=kafka-python-2.0.5, node_id=3 host=b3-pkc-41wq6.eu-west-2.aws.confluent.cloud:9092 <authenticating> [IPv4 ('13.43.118.221', 9092)]>: Authenticated as XGISOSVJLGK43N6I via PLAIN
[2025-03-04T20:19:53.677+0000] {conn.py:449} INFO - <BrokerConnection client_id=kafka-python-2.0.5, node_id=3 host=b3-pkc-41wq6.eu-west-2.aws.confluent.cloud:9092 <authenticating> [IPv4 ('13.43.118.221', 9092)]>: Connection complete.
[2025-03-04T20:19:53.830+0000] {conn.py:384} INFO - <BrokerConnection client_id=kafka-python-2.0.5, node_id=0 host=b0-pkc-41wq6.eu-west-2.aws.confluent.cloud:9092 <connecting> [IPv4 ('13.43.16.9', 9092)]>: connecting to b0-pkc-41wq6.eu-west-2.aws.confluent.cloud:9092 [('13.43.16.9', 9092) IPv4]
[2025-03-04T20:19:53.937+0000] {conn.py:480} INFO - <BrokerConnection client_id=kafka-python-2.0.5, node_id=0 host=b0-pkc-41wq6.eu-west-2.aws.confluent.cloud:9092 <handshake> [IPv4 ('13.43.16.9', 9092)]>: Loading system default SSL CAs from ('/usr/lib/ssl/cert.pem', '/usr/lib/ssl/certs', 'SSL_CERT_FILE', '/usr/lib/ssl/cert.pem', 'SSL_CERT_DIR', '/usr/lib/ssl/certs')
[2025-03-04T20:19:54.432+0000] {conn.py:665} INFO - <BrokerConnection client_id=kafka-python-2.0.5, node_id=0 host=b0-pkc-41wq6.eu-west-2.aws.confluent.cloud:9092 <authenticating> [IPv4 ('13.43.16.9', 9092)]>: Authenticated as XGISOSVJLGK43N6I via PLAIN
[2025-03-04T20:19:54.433+0000] {conn.py:449} INFO - <BrokerConnection client_id=kafka-python-2.0.5, node_id=0 host=b0-pkc-41wq6.eu-west-2.aws.confluent.cloud:9092 <authenticating> [IPv4 ('13.43.16.9', 9092)]>: Connection complete.
[2025-03-04T20:20:11.051+0000] {conn.py:928} INFO - <BrokerConnection client_id=kafka-python-2.0.5, node_id=4 host=b4-pkc-41wq6.eu-west-2.aws.confluent.cloud:9092 <connected> [IPv4 ('52.56.207.193', 9092)]>: Closing connection. 
[2025-03-04T20:20:11.063+0000] {fetcher.py:782} INFO - Fetch to node 4 failed: Cancelled: <BrokerConnection client_id=kafka-python-2.0.5, node_id=4 host=b4-pkc-41wq6.eu-west-2.aws.confluent.cloud:9092 <connected> [IPv4 ('52.56.207.193', 9092)]>
[2025-03-04T20:20:11.064+0000] {conn.py:928} INFO - <BrokerConnection client_id=kafka-python-2.0.5, node_id=1 host=b1-pkc-41wq6.eu-west-2.aws.confluent.cloud:9092 <connected> [IPv4 ('18.169.23.80', 9092)]>: Closing connection. 
[2025-03-04T20:20:11.066+0000] {fetcher.py:782} INFO - Fetch to node 1 failed: Cancelled: <BrokerConnection client_id=kafka-python-2.0.5, node_id=1 host=b1-pkc-41wq6.eu-west-2.aws.confluent.cloud:9092 <connected> [IPv4 ('18.169.23.80', 9092)]>
[2025-03-04T20:20:11.067+0000] {conn.py:928} INFO - <BrokerConnection client_id=kafka-python-2.0.5, node_id=2 host=b2-pkc-41wq6.eu-west-2.aws.confluent.cloud:9092 <connected> [IPv4 ('13.43.33.231', 9092)]>: Closing connection. 
[2025-03-04T20:20:11.067+0000] {fetcher.py:782} INFO - Fetch to node 2 failed: Cancelled: <BrokerConnection client_id=kafka-python-2.0.5, node_id=2 host=b2-pkc-41wq6.eu-west-2.aws.confluent.cloud:9092 <connected> [IPv4 ('13.43.33.231', 9092)]>
[2025-03-04T20:20:11.068+0000] {conn.py:928} INFO - <BrokerConnection client_id=kafka-python-2.0.5, node_id=5 host=b5-pkc-41wq6.eu-west-2.aws.confluent.cloud:9092 <connected> [IPv4 ('51.24.25.161', 9092)]>: Closing connection. 
[2025-03-04T20:20:11.068+0000] {fetcher.py:782} INFO - Fetch to node 5 failed: Cancelled: <BrokerConnection client_id=kafka-python-2.0.5, node_id=5 host=b5-pkc-41wq6.eu-west-2.aws.confluent.cloud:9092 <connected> [IPv4 ('51.24.25.161', 9092)]>
[2025-03-04T20:20:11.069+0000] {conn.py:928} INFO - <BrokerConnection client_id=kafka-python-2.0.5, node_id=3 host=b3-pkc-41wq6.eu-west-2.aws.confluent.cloud:9092 <connected> [IPv4 ('13.43.118.221', 9092)]>: Closing connection. 
[2025-03-04T20:20:11.069+0000] {fetcher.py:782} INFO - Fetch to node 3 failed: Cancelled: <BrokerConnection client_id=kafka-python-2.0.5, node_id=3 host=b3-pkc-41wq6.eu-west-2.aws.confluent.cloud:9092 <connected> [IPv4 ('13.43.118.221', 9092)]>
[2025-03-04T20:20:11.069+0000] {conn.py:928} INFO - <BrokerConnection client_id=kafka-python-2.0.5, node_id=0 host=b0-pkc-41wq6.eu-west-2.aws.confluent.cloud:9092 <connected> [IPv4 ('13.43.16.9', 9092)]>: Closing connection. 
[2025-03-04T20:20:11.070+0000] {fetcher.py:782} INFO - Fetch to node 0 failed: Cancelled: <BrokerConnection client_id=kafka-python-2.0.5, node_id=0 host=b0-pkc-41wq6.eu-west-2.aws.confluent.cloud:9092 <connected> [IPv4 ('13.43.16.9', 9092)]>
[2025-03-04T20:20:12.630+0000] {fraud_detection_training.py:124} INFO - Kafka data read successfully with fraud rate: 0.38%
[2025-03-04T20:20:19.991+0000] {fraud_detection_training.py:249} INFO - Starting hyperparameter tuning...
[2025-03-04T20:20:19.997+0000] {warnings.py:112} WARNING - /home/***/.local/lib/python3.12/site-packages/joblib/parallel.py:1359: UserWarning: Loky-backed parallel loops cannot be called in a multiprocessing, setting n_jobs=1
  n_jobs = self._backend.configure(n_jobs=self.n_jobs, parallel=self,

[2025-03-04T20:24:04.801+0000] {fraud_detection_training.py:253} INFO - Best hyperparameters: {'classifier__subsample': 0.6, 'classifier__reg_alpha': 0, 'classifier__max_depth': 5, 'classifier__learning_rate': 0.1, 'classifier__gamma': 0.3, 'classifier__colsample_bytree': 0.8}
[2025-03-04T20:24:05.414+0000] {fraud_detection_training.py:259} INFO - Optimal threshold determined: 0.8057
[2025-03-04T20:24:07.106+0000] {credentials.py:1147} INFO - Found credentials in environment variables.
[2025-03-04T20:24:08.107+0000] {warnings.py:112} WARNING - /home/***/.local/lib/python3.12/site-packages/mlflow/types/utils.py:452: UserWarning: Hint: Inferred schema contains integer column(s). Integer columns in Python cannot represent missing values. If your input data contains missing values at inference time, it will be encoded as floats and will cause a schema enforcement error. The best way to avoid this problem is to infer the model schema based on a realistic data sample (training dataset) that includes missing values. Alternatively, you can declare integer columns as doubles (float64) whenever these columns may have missing values. See `Handling Integers With Missing Values <https://www.mlflow.org/docs/latest/models.html#handling-integers-with-missing-values>`_ for more details.
  warnings.warn(

[2025-03-04T20:24:15.698+0000] {logging_mixin.py:190} WARNING - Registered model 'fraud_detection_model' already exists. Creating a new version of this model...
[2025-03-04T20:24:15.801+0000] {logging_mixin.py:190} WARNING - 2025/03/04 20:24:15 INFO mlflow.store.model_registry.abstract_store: Waiting up to 300 seconds for model version to finish creation. Model name: fraud_detection_model, version 3
[2025-03-04T20:24:15.802+0000] {logging_mixin.py:190} WARNING - Created version '3' of model 'fraud_detection_model'.
[2025-03-04T20:24:15.831+0000] {logging_mixin.py:190} INFO - 🏃 View run bold-pug-159 at: http://mlflow-server:5500/#/experiments/1/runs/466a938261254092acfbd40519137e56
[2025-03-04T20:24:15.832+0000] {logging_mixin.py:190} INFO - 🧪 View experiment at: http://mlflow-server:5500/#/experiments/1
[2025-03-04T20:24:15.847+0000] {fraud_detection_training.py:326} ERROR - Training failed: [Errno 2] No such file or directory: '/app/models/fraud_detection_model.pkl'
Traceback (most recent call last):
  File "/opt/airflow/dags/fraud_detection_training.py", line 319, in train_model
    mlflow.log_artifact('/app/models/fraud_detection_model.pkl')
  File "/home/airflow/.local/lib/python3.12/site-packages/mlflow/tracking/fluent.py", line 1179, in log_artifact
    MlflowClient().log_artifact(run_id, local_path, artifact_path)
  File "/home/airflow/.local/lib/python3.12/site-packages/mlflow/tracking/client.py", line 2000, in log_artifact
    self._tracking_client.log_artifact(run_id, local_path, artifact_path)
  File "/home/airflow/.local/lib/python3.12/site-packages/mlflow/tracking/_tracking_service/client.py", line 926, in log_artifact
    artifact_repo.log_artifact(local_path, artifact_path)
  File "/home/airflow/.local/lib/python3.12/site-packages/mlflow/store/artifact/s3_artifact_repo.py", line 176, in log_artifact
    self._upload_file(
  File "/home/airflow/.local/lib/python3.12/site-packages/mlflow/store/artifact/s3_artifact_repo.py", line 169, in _upload_file
    s3_client.upload_file(Filename=local_file, Bucket=bucket, Key=key, ExtraArgs=extra_args)
  File "/home/airflow/.local/lib/python3.12/site-packages/boto3/s3/inject.py", line 145, in upload_file
    return transfer.upload_file(
           ^^^^^^^^^^^^^^^^^^^^^
  File "/home/airflow/.local/lib/python3.12/site-packages/boto3/s3/transfer.py", line 372, in upload_file
    future.result()
  File "/home/airflow/.local/lib/python3.12/site-packages/s3transfer/futures.py", line 103, in result
    return self._coordinator.result()
           ^^^^^^^^^^^^^^^^^^^^^^^^^^
  File "/home/airflow/.local/lib/python3.12/site-packages/s3transfer/futures.py", line 264, in result
    raise self._exception
  File "/home/airflow/.local/lib/python3.12/site-packages/s3transfer/tasks.py", line 265, in _main
    self._submit(transfer_future=transfer_future, **kwargs)
  File "/home/airflow/.local/lib/python3.12/site-packages/s3transfer/upload.py", line 596, in _submit
    upload_input_manager.provide_transfer_size(transfer_future)
  File "/home/airflow/.local/lib/python3.12/site-packages/s3transfer/upload.py", line 245, in provide_transfer_size
    self._osutil.get_file_size(transfer_future.meta.call_args.fileobj)
  File "/home/airflow/.local/lib/python3.12/site-packages/s3transfer/utils.py", line 262, in get_file_size
    return os.path.getsize(filename)
           ^^^^^^^^^^^^^^^^^^^^^^^^^
  File "<frozen genericpath>", line 62, in getsize
FileNotFoundError: [Errno 2] No such file or directory: '/app/models/fraud_detection_model.pkl'
[2025-03-04T20:24:15.871+0000] {fraud_detection_training_dag.py:29} ERROR - Training failed: [Errno 2] No such file or directory: '/app/models/fraud_detection_model.pkl'
Traceback (most recent call last):
  File "/opt/airflow/dags/fraud_detection_training_dag.py", line 25, in _train_model
    model, precision = trainer.train_model()
                       ^^^^^^^^^^^^^^^^^^^^^
  File "/opt/airflow/dags/fraud_detection_training.py", line 319, in train_model
    mlflow.log_artifact('/app/models/fraud_detection_model.pkl')
  File "/home/airflow/.local/lib/python3.12/site-packages/mlflow/tracking/fluent.py", line 1179, in log_artifact
    MlflowClient().log_artifact(run_id, local_path, artifact_path)
  File "/home/airflow/.local/lib/python3.12/site-packages/mlflow/tracking/client.py", line 2000, in log_artifact
    self._tracking_client.log_artifact(run_id, local_path, artifact_path)
  File "/home/airflow/.local/lib/python3.12/site-packages/mlflow/tracking/_tracking_service/client.py", line 926, in log_artifact
    artifact_repo.log_artifact(local_path, artifact_path)
  File "/home/airflow/.local/lib/python3.12/site-packages/mlflow/store/artifact/s3_artifact_repo.py", line 176, in log_artifact
    self._upload_file(
  File "/home/airflow/.local/lib/python3.12/site-packages/mlflow/store/artifact/s3_artifact_repo.py", line 169, in _upload_file
    s3_client.upload_file(Filename=local_file, Bucket=bucket, Key=key, ExtraArgs=extra_args)
  File "/home/airflow/.local/lib/python3.12/site-packages/boto3/s3/inject.py", line 145, in upload_file
    return transfer.upload_file(
           ^^^^^^^^^^^^^^^^^^^^^
  File "/home/airflow/.local/lib/python3.12/site-packages/boto3/s3/transfer.py", line 372, in upload_file
    future.result()
  File "/home/airflow/.local/lib/python3.12/site-packages/s3transfer/futures.py", line 103, in result
    return self._coordinator.result()
           ^^^^^^^^^^^^^^^^^^^^^^^^^^
  File "/home/airflow/.local/lib/python3.12/site-packages/s3transfer/futures.py", line 264, in result
    raise self._exception
  File "/home/airflow/.local/lib/python3.12/site-packages/s3transfer/tasks.py", line 265, in _main
    self._submit(transfer_future=transfer_future, **kwargs)
  File "/home/airflow/.local/lib/python3.12/site-packages/s3transfer/upload.py", line 596, in _submit
    upload_input_manager.provide_transfer_size(transfer_future)
  File "/home/airflow/.local/lib/python3.12/site-packages/s3transfer/upload.py", line 245, in provide_transfer_size
    self._osutil.get_file_size(transfer_future.meta.call_args.fileobj)
  File "/home/airflow/.local/lib/python3.12/site-packages/s3transfer/utils.py", line 262, in get_file_size
    return os.path.getsize(filename)
           ^^^^^^^^^^^^^^^^^^^^^^^^^
  File "<frozen genericpath>", line 62, in getsize
FileNotFoundError: [Errno 2] No such file or directory: '/app/models/fraud_detection_model.pkl'
[2025-03-04T20:24:15.929+0000] {taskinstance.py:3313} ERROR - Task failed with exception
Traceback (most recent call last):
  File "/opt/airflow/dags/fraud_detection_training_dag.py", line 25, in _train_model
    model, precision = trainer.train_model()
                       ^^^^^^^^^^^^^^^^^^^^^
  File "/opt/airflow/dags/fraud_detection_training.py", line 319, in train_model
    mlflow.log_artifact('/app/models/fraud_detection_model.pkl')
  File "/home/airflow/.local/lib/python3.12/site-packages/mlflow/tracking/fluent.py", line 1179, in log_artifact
    MlflowClient().log_artifact(run_id, local_path, artifact_path)
  File "/home/airflow/.local/lib/python3.12/site-packages/mlflow/tracking/client.py", line 2000, in log_artifact
    self._tracking_client.log_artifact(run_id, local_path, artifact_path)
  File "/home/airflow/.local/lib/python3.12/site-packages/mlflow/tracking/_tracking_service/client.py", line 926, in log_artifact
    artifact_repo.log_artifact(local_path, artifact_path)
  File "/home/airflow/.local/lib/python3.12/site-packages/mlflow/store/artifact/s3_artifact_repo.py", line 176, in log_artifact
    self._upload_file(
  File "/home/airflow/.local/lib/python3.12/site-packages/mlflow/store/artifact/s3_artifact_repo.py", line 169, in _upload_file
    s3_client.upload_file(Filename=local_file, Bucket=bucket, Key=key, ExtraArgs=extra_args)
  File "/home/airflow/.local/lib/python3.12/site-packages/boto3/s3/inject.py", line 145, in upload_file
    return transfer.upload_file(
           ^^^^^^^^^^^^^^^^^^^^^
  File "/home/airflow/.local/lib/python3.12/site-packages/boto3/s3/transfer.py", line 372, in upload_file
    future.result()
  File "/home/airflow/.local/lib/python3.12/site-packages/s3transfer/futures.py", line 103, in result
    return self._coordinator.result()
           ^^^^^^^^^^^^^^^^^^^^^^^^^^
  File "/home/airflow/.local/lib/python3.12/site-packages/s3transfer/futures.py", line 264, in result
    raise self._exception
  File "/home/airflow/.local/lib/python3.12/site-packages/s3transfer/tasks.py", line 265, in _main
    self._submit(transfer_future=transfer_future, **kwargs)
  File "/home/airflow/.local/lib/python3.12/site-packages/s3transfer/upload.py", line 596, in _submit
    upload_input_manager.provide_transfer_size(transfer_future)
  File "/home/airflow/.local/lib/python3.12/site-packages/s3transfer/upload.py", line 245, in provide_transfer_size
    self._osutil.get_file_size(transfer_future.meta.call_args.fileobj)
  File "/home/airflow/.local/lib/python3.12/site-packages/s3transfer/utils.py", line 262, in get_file_size
    return os.path.getsize(filename)
           ^^^^^^^^^^^^^^^^^^^^^^^^^
  File "<frozen genericpath>", line 62, in getsize
FileNotFoundError: [Errno 2] No such file or directory: '/app/models/fraud_detection_model.pkl'

During handling of the above exception, another exception occurred:

Traceback (most recent call last):
  File "/home/airflow/.local/lib/python3.12/site-packages/airflow/models/taskinstance.py", line 768, in _execute_task
    result = _execute_callable(context=context, **execute_callable_kwargs)
             ^^^^^^^^^^^^^^^^^^^^^^^^^^^^^^^^^^^^^^^^^^^^^^^^^^^^^^^^^^^^^
  File "/home/airflow/.local/lib/python3.12/site-packages/airflow/models/taskinstance.py", line 734, in _execute_callable
    return ExecutionCallableRunner(
           ^^^^^^^^^^^^^^^^^^^^^^^^
  File "/home/airflow/.local/lib/python3.12/site-packages/airflow/utils/operator_helpers.py", line 252, in run
    return self.func(*args, **kwargs)
           ^^^^^^^^^^^^^^^^^^^^^^^^^^
  File "/home/airflow/.local/lib/python3.12/site-packages/airflow/models/baseoperator.py", line 424, in wrapper
    return func(self, *args, **kwargs)
           ^^^^^^^^^^^^^^^^^^^^^^^^^^^
  File "/home/airflow/.local/lib/python3.12/site-packages/airflow/operators/python.py", line 238, in execute
    return_value = self.execute_callable()
                   ^^^^^^^^^^^^^^^^^^^^^^^
  File "/home/airflow/.local/lib/python3.12/site-packages/airflow/operators/python.py", line 256, in execute_callable
    return runner.run(*self.op_args, **self.op_kwargs)
           ^^^^^^^^^^^^^^^^^^^^^^^^^^^^^^^^^^^^^^^^^^^
  File "/home/airflow/.local/lib/python3.12/site-packages/airflow/utils/operator_helpers.py", line 252, in run
    return self.func(*args, **kwargs)
           ^^^^^^^^^^^^^^^^^^^^^^^^^^
  File "/opt/airflow/dags/fraud_detection_training_dag.py", line 30, in _train_model
    raise AirflowException(f'Model training failed: {str(e)}')
airflow.exceptions.AirflowException: Model training failed: [Errno 2] No such file or directory: '/app/models/fraud_detection_model.pkl'
[2025-03-04T20:24:15.946+0000] {taskinstance.py:1226} INFO - Marking task as FAILED. dag_id=fraud_detection_training, task_id=execute_training, run_id=manual__2025-03-04T20:19:36.656268+00:00, execution_date=20250304T201936, start_date=20250304T201942, end_date=20250304T202415
[2025-03-04T20:24:16.110+0000] {taskinstance.py:341} INFO - ::group::Post task execution logs
[2025-03-04T20:24:16.111+0000] {standard_task_runner.py:124} ERROR - Failed to execute job 28 for task execute_training (Model training failed: [Errno 2] No such file or directory: '/app/models/fraud_detection_model.pkl'; 9349)
Traceback (most recent call last):
  File "/opt/airflow/dags/fraud_detection_training_dag.py", line 25, in _train_model
    model, precision = trainer.train_model()
                       ^^^^^^^^^^^^^^^^^^^^^
  File "/opt/airflow/dags/fraud_detection_training.py", line 319, in train_model
    mlflow.log_artifact('/app/models/fraud_detection_model.pkl')
  File "/home/airflow/.local/lib/python3.12/site-packages/mlflow/tracking/fluent.py", line 1179, in log_artifact
    MlflowClient().log_artifact(run_id, local_path, artifact_path)
  File "/home/airflow/.local/lib/python3.12/site-packages/mlflow/tracking/client.py", line 2000, in log_artifact
    self._tracking_client.log_artifact(run_id, local_path, artifact_path)
  File "/home/airflow/.local/lib/python3.12/site-packages/mlflow/tracking/_tracking_service/client.py", line 926, in log_artifact
    artifact_repo.log_artifact(local_path, artifact_path)
  File "/home/airflow/.local/lib/python3.12/site-packages/mlflow/store/artifact/s3_artifact_repo.py", line 176, in log_artifact
    self._upload_file(
  File "/home/airflow/.local/lib/python3.12/site-packages/mlflow/store/artifact/s3_artifact_repo.py", line 169, in _upload_file
    s3_client.upload_file(Filename=local_file, Bucket=bucket, Key=key, ExtraArgs=extra_args)
  File "/home/airflow/.local/lib/python3.12/site-packages/boto3/s3/inject.py", line 145, in upload_file
    return transfer.upload_file(
           ^^^^^^^^^^^^^^^^^^^^^
  File "/home/airflow/.local/lib/python3.12/site-packages/boto3/s3/transfer.py", line 372, in upload_file
    future.result()
  File "/home/airflow/.local/lib/python3.12/site-packages/s3transfer/futures.py", line 103, in result
    return self._coordinator.result()
           ^^^^^^^^^^^^^^^^^^^^^^^^^^
  File "/home/airflow/.local/lib/python3.12/site-packages/s3transfer/futures.py", line 264, in result
    raise self._exception
  File "/home/airflow/.local/lib/python3.12/site-packages/s3transfer/tasks.py", line 265, in _main
    self._submit(transfer_future=transfer_future, **kwargs)
  File "/home/airflow/.local/lib/python3.12/site-packages/s3transfer/upload.py", line 596, in _submit
    upload_input_manager.provide_transfer_size(transfer_future)
  File "/home/airflow/.local/lib/python3.12/site-packages/s3transfer/upload.py", line 245, in provide_transfer_size
    self._osutil.get_file_size(transfer_future.meta.call_args.fileobj)
  File "/home/airflow/.local/lib/python3.12/site-packages/s3transfer/utils.py", line 262, in get_file_size
    return os.path.getsize(filename)
           ^^^^^^^^^^^^^^^^^^^^^^^^^
  File "<frozen genericpath>", line 62, in getsize
FileNotFoundError: [Errno 2] No such file or directory: '/app/models/fraud_detection_model.pkl'

During handling of the above exception, another exception occurred:

Traceback (most recent call last):
  File "/home/airflow/.local/lib/python3.12/site-packages/airflow/task/task_runner/standard_task_runner.py", line 117, in _start_by_fork
    ret = args.func(args, dag=self.dag)
          ^^^^^^^^^^^^^^^^^^^^^^^^^^^^^
  File "/home/airflow/.local/lib/python3.12/site-packages/airflow/cli/cli_config.py", line 49, in command
    return func(*args, **kwargs)
           ^^^^^^^^^^^^^^^^^^^^^
  File "/home/airflow/.local/lib/python3.12/site-packages/airflow/utils/cli.py", line 116, in wrapper
    return f(*args, **kwargs)
           ^^^^^^^^^^^^^^^^^^
  File "/home/airflow/.local/lib/python3.12/site-packages/airflow/cli/commands/task_command.py", line 483, in task_run
    task_return_code = _run_task_by_selected_method(args, _dag, ti)
                       ^^^^^^^^^^^^^^^^^^^^^^^^^^^^^^^^^^^^^^^^^^^^
  File "/home/airflow/.local/lib/python3.12/site-packages/airflow/cli/commands/task_command.py", line 256, in _run_task_by_selected_method
    return _run_raw_task(args, ti)
           ^^^^^^^^^^^^^^^^^^^^^^^
  File "/home/airflow/.local/lib/python3.12/site-packages/airflow/cli/commands/task_command.py", line 341, in _run_raw_task
    return ti._run_raw_task(
           ^^^^^^^^^^^^^^^^^
  File "/home/airflow/.local/lib/python3.12/site-packages/airflow/utils/session.py", line 97, in wrapper
    return func(*args, session=session, **kwargs)
           ^^^^^^^^^^^^^^^^^^^^^^^^^^^^^^^^^^^^^^
  File "/home/airflow/.local/lib/python3.12/site-packages/airflow/models/taskinstance.py", line 3006, in _run_raw_task
    return _run_raw_task(
           ^^^^^^^^^^^^^^
  File "/home/airflow/.local/lib/python3.12/site-packages/airflow/models/taskinstance.py", line 274, in _run_raw_task
    TaskInstance._execute_task_with_callbacks(
  File "/home/airflow/.local/lib/python3.12/site-packages/airflow/models/taskinstance.py", line 3161, in _execute_task_with_callbacks
    result = self._execute_task(context, task_orig)
             ^^^^^^^^^^^^^^^^^^^^^^^^^^^^^^^^^^^^^^
  File "/home/airflow/.local/lib/python3.12/site-packages/airflow/models/taskinstance.py", line 3185, in _execute_task
    return _execute_task(self, context, task_orig)
           ^^^^^^^^^^^^^^^^^^^^^^^^^^^^^^^^^^^^^^^
  File "/home/airflow/.local/lib/python3.12/site-packages/airflow/models/taskinstance.py", line 768, in _execute_task
    result = _execute_callable(context=context, **execute_callable_kwargs)
             ^^^^^^^^^^^^^^^^^^^^^^^^^^^^^^^^^^^^^^^^^^^^^^^^^^^^^^^^^^^^^
  File "/home/airflow/.local/lib/python3.12/site-packages/airflow/models/taskinstance.py", line 734, in _execute_callable
    return ExecutionCallableRunner(
           ^^^^^^^^^^^^^^^^^^^^^^^^
  File "/home/airflow/.local/lib/python3.12/site-packages/airflow/utils/operator_helpers.py", line 252, in run
    return self.func(*args, **kwargs)
           ^^^^^^^^^^^^^^^^^^^^^^^^^^
  File "/home/airflow/.local/lib/python3.12/site-packages/airflow/models/baseoperator.py", line 424, in wrapper
    return func(self, *args, **kwargs)
           ^^^^^^^^^^^^^^^^^^^^^^^^^^^
  File "/home/airflow/.local/lib/python3.12/site-packages/airflow/operators/python.py", line 238, in execute
    return_value = self.execute_callable()
                   ^^^^^^^^^^^^^^^^^^^^^^^
  File "/home/airflow/.local/lib/python3.12/site-packages/airflow/operators/python.py", line 256, in execute_callable
    return runner.run(*self.op_args, **self.op_kwargs)
           ^^^^^^^^^^^^^^^^^^^^^^^^^^^^^^^^^^^^^^^^^^^
  File "/home/airflow/.local/lib/python3.12/site-packages/airflow/utils/operator_helpers.py", line 252, in run
    return self.func(*args, **kwargs)
           ^^^^^^^^^^^^^^^^^^^^^^^^^^
  File "/opt/airflow/dags/fraud_detection_training_dag.py", line 30, in _train_model
    raise AirflowException(f'Model training failed: {str(e)}')
airflow.exceptions.AirflowException: Model training failed: [Errno 2] No such file or directory: '/app/models/fraud_detection_model.pkl'
[2025-03-04T20:24:16.168+0000] {local_task_job_runner.py:266} INFO - Task exited with return code 1
[2025-03-04T20:24:16.263+0000] {taskinstance.py:3901} INFO - 1 downstream tasks scheduled from follow-on schedule check
[2025-03-04T20:24:16.266+0000] {local_task_job_runner.py:245} INFO - ::endgroup::
